Workbook

Sheet Picks for Review (Sep 26)
A1: Series Name | B1: Author | C1: Sub-Genre | D1: Book Series (GoodReads URL) | E1: GoodReads No. of Ratings | F1: Goodreads Book 1 Ratings | G1: Total Primary Books | H1: Total primary Books Page Count | I1: Imprint / Publisher - Book | J1: Agencies | K1: Imprint / Publisher - Audiobook | L1: Crawling POC | M1: Crawling Date | N1: Links addition POC | O1: Links Date | P1: Book 1 Link | Q1: Books (1 - 5) Links | R1: Antigravity QC | S1: Batch Number
A2: The Twilight Saga | B2: Stephenie Meyer | C2: Gothic Dark Romantasy | D2: https://www.goodreads.com/series/45363-the-twilight-saga | E2: 7485263 | F2: 3.68 | G2: 9 | H2: 4817 | I2: ) Format: Audible Audiobook | J2: New Keywords - Amazon | L2: Sakshi Saxena | P2: 1_Twilight_-_Stephenie_Meyer.docx | Q2: The Twilight Saga | S2: Batch 2 Review
A3: Green Creek | B3: Kelly Bennett | C3: Paranormal Romance | D3: https://www.goodreads.com/series/206510-green-creek | E3: 118376 | F3: 4.18 | G3: 4 | H3: 118376 | I3: Indie / Self-Published | J3: Metamorphosis Literary Agency | L3: Vanshika V | M3: 46283 | N3: Vanshika V | P3: https://docs.google.com/document/d/102Co9URvI7NHwz65ofheImstJmx3_C2w/edit?usp=drive_link&ouid=101023058405307348147&rtpof=true&sd=true | Q3: https://drive.google.com/drive/folders/15WyC66FwRnei2POYs01P4BHDFr_5dLPr?usp=drive_link | S3: Batch 1 Review
A4: Air Awakens | B4: Elise Fender Burns | C4: High Fantasy Court Adventure | D4: https://www.goodreads.com/series/155275-air-awakens | E4: 63472 | F4: 3.97 | G4: 5 | H4: 63472 | I4: Indie / Self-Published | J4: Metamorphosis Literary Agency | L4: Vanshika V | M4: 46283 | N4: Vanshika V | P4: https://docs.google.com/document/d/1a42Nqridsbx5sLJgnfsjtz_tM0HKN4Lm/edit?usp=drive_link&ouid=101023058405307348147&rtpof=true&sd=true | Q4: https://drive.google.com/drive/folders/1Z8o5jSlW3Bq8CpAyuYG0Opo3jnRKwAqb?usp=drive_link | S4: Batch 1 Review
A5: Warrior Security | B5: Brittany Cooper | C5: High-Stakes Games & Deadly Trials | D5: https://www.goodreads.com/series/426999-warrior-security | E5: 2310 | F5: 4.47 | G5: 5 | H5: 2310 | I5: Indie / Self-Published | J5: Metamorphosis Literary Agency | L5: Vanshika V | M5: 46283 | N5: Vanshika V | P5: https://docs.google.com/document/d/1uGe-oUialP2el1Y3fhEazOkMe1ixL1Sf/edit?usp=drive_link&ouid=101023058405307348147&rtpof=true&sd=true | Q5: https://drive.google.com/drive/folders/1GRRhk2RsoERxTDphHtU0G_6kKP5UTafA?usp=drive_link | S5: Batch 1 Review
A6: The Shadowhunter Chronicles | B6: Claire Karwowski | C6: Urban / Contemporary Fantasy Romance | D6: https://www.goodreads.com/series/242806-the-shadowhunter-chronicles | E6: 2207639 | F6: 4.06 | G6: 26 | H6: 12245 | I6: Indie / Self-Published | J6: Jane Rotrosen Agency | L6: Sakshi Saxena | P6: 1_City_of_Bones_-_Cassandra_Clare.docx | Q6: The Shadowhunter Chronicles | S6: Batch 2 Review
A7: The Queen's Alpha Series | B7: Teresa Gabelman | C7: High Fantasy Court Adventure | D7: https://www.goodreads.com/series/264896-the-queen-s-alpha | E7: 1808109 | F7: 3.9 | G7: 12 | H7: 2518 | I7: Indie / Self-Published | J7: New Keywords - Amazon | L7: Sakshi Saxena | P7: 1_Eternal_-_W_J_May.docx | Q7: The Queen S Alpha | S7: Batch 2 Review
A8: Summer Court | B8: Gena Showalter | C8: High Fantasy Court Adventure | D8: https://www.goodreads.com/series/348188-summer-court | E8: 1807664 | F8: 3.31 | G8: 8 | H8: 2039 | I8: Indie / Self-Published | J8: New Keywords - Amazon | L8: Sakshi Saxena | P8: 1_Faes_Song_-_Helen_Walton.docx | Q8: Summer Court | S8: Batch 2 Review
A9: Fire And Fang | B9: Lindsay Flanagan | C9: High Fantasy Court Adventure | D9: https://www.goodreads.com/series/428113-fire-and-fang | E9: 3087 | F9: 4.07 | G9: 5 | H9: 3087 | I9: Indie / Self-Published | J9: Metamorphosis Literary Agency | L9: Vanshika V | M9: 46283 | N9: Vanshika V | P9: https://docs.google.com/document/d/1pDpQYoA6iNGrpTRf35YkQ72AulEuFaRE/edit?usp=drive_link&ouid=101023058405307348147&rtpof=true&sd=true | Q9: https://drive.google.com/drive/folders/11Ac4Iz28Vn5AQpHld3YGDFg2606IfaR6?usp=drive_link | S9: Batch 1 Review
A10: The Coven: Elemental Magic | B10: Chandelle LaVaun | C10: Paranormal Romance ( Done ) | D10: https://www.goodreads.com/series/234103-the-coven-elemental-magic | E10: 1276274 | F10: 4.18 | G10: 7 | H10: 2948 | I10: Wanderlost Publishing | J10: New Keywords - Amazon | L10: Sakshi Saxena | P10: 1_The_Lost_Witch_-_Chandelle_LaVaun.docx | Q10: The Coven Elemental Magic | S10: Batch 2 Review
A11: Shatter Me | B11: Tahereh Mafi | C11: Paranormal Romance | D11: https://www.goodreads.com/series/65730-shatter-me | E11: 1260128 | F11: 3.84 | G11: 12 | H11: 2481 | I11: Storytide | K11: Storytide | L11: Noel Regis | M11: 46282 | P11: 1_Shatter Me.docx | Q11: 11_Shatter Me | S11: Batch 1 Review
A12: This Woven Kingdom | B12: Tiffany W. Killoren | C12: Mythology, Legend & Fairy Tale Retelling | D12: https://www.goodreads.com/series/319224-this-woven-kingdom | E12: 119741 | F12: 4.28 | G12: 5 | H12: 119741 | I12: Indie / Self-Published | J12: Metamorphosis Literary Agency | L12: Vanshika V | M12: 46283 | N12: Vanshika V | P12: https://docs.google.com/document/d/1wxQ6oyhK93uhZ1Vu_KLr2C3GVXtcOz_k/edit?usp=drive_link&ouid=101023058405307348147&rtpof=true&sd=true | Q12: https://drive.google.com/drive/folders/11ZUWyaB1f9-L9YCg_WmD7oXTFWU3wwEU?usp=drive_link | S12: Batch 1 Review
A13: The Inheritance Games | B13: Angela Crocker | C13: High-Stakes Games & Deadly Trials | D13: https://www.goodreads.com/series/53144-angel | E13: 1142005 | F13: 3.85 | G13: 3 | H13: 1723 | I13: Indie / Self-Published | J13: Metamorphosis Literary Agency | L13: Sakshi Saxena | P13: 1_Angel_Burn_-_L_A_Weatherly.docx | Q13: Angel Series | S13: Batch 2 Review
A14: Tiffany Black Mysteries | B14: Tiffany W. Killoren | C14: Cozy / Cottagecore Romantasy | D14: https://www.goodreads.com/series/124119-tiffany-black-mysteries | E14: 10545 | F14: 3.71 | G14: 37 | H14: 10545 | I14: Indie / Self-Published | J14: Metamorphosis Literary Agency | L14: Vanshika V | M14: 46283 | N14: Vanshika V | P14: https://docs.google.com/document/d/1ALVv-mpE7V69_4xV4EZZQBBOL08me4xH/edit?usp=drive_link&ouid=101023058405307348147&rtpof=true&sd=true | Q14: https://drive.google.com/drive/folders/1mH43uDPXFbMxk1g9WCgnxqnt-IJgjqmS?usp=drive_link | S14: Batch 1 Review
A15: Arcane Society | B15: Mike Krentz | C15: Paranormal Romance | D15: https://www.goodreads.com/series/57569-arcane-society | E15: 16119 | F15: 3.91 | G15: 12 | H15: 16119 | I15: Indie / Self-Published | J15: Metamorphosis Literary Agency | L15: Vanshika V | M15: 46283 | N15: Vanshika V | P15: https://docs.google.com/document/d/1WKhrsKagyScv3YdVnxwWaAPu3H37_vc6/edit?usp=drive_link&ouid=101023058405307348147&rtpof=true&sd=true | Q15: https://drive.google.com/drive/folders/1BCNS4Cq-JEWdGzXyBnoiW81CzBAbnWoS?usp=drive_link | S15: Batch 1 Review
A16: Fae & Alchemy | B16: Callie Hart | C16: High Fantasy Court Adventure | D16: https://www.goodreads.com/series/392242-fae-alchemy | E16: 987885 | F16: 4.3 | G16: 4 | H16: 3216 | I16: Podium Audio | J16: New Keywords - Amazon | L16: Noel Regis | M16: 46282 | P16: 1_Quicksilver_-_Callie_Hart.docx | Q16: Fae & Alchemy Series | S16: Batch 1 Review
A17: Red Rising | B17: Pierce Brown | C17: Paranormal Romance | D17: https://www.goodreads.com/series/117100-red-rising-saga | E17: 853673 | F17: 4.27 | G17: 18 | H17: 8359 | I17: Recorded Books | K17: Recorded Books | L17: Noel Regis | M17: 46282 | N17: Sakshi Saxena | O17: 46286 | P17: 1_Red Rising.docx | Q17: 17_Red Rising Saga by Pierce Brown | S17: Batch 1 Review
A18: The Witchlands | B18: Kathy MacMillan | C18: High Fantasy Court Adventure | D18: https://www.goodreads.com/series/124183-the-witchlands | E18: 53820 | F18: 3.84 | G18: 5 | H18: 53820 | I18: Indie / Self-Published | J18: Metamorphosis Literary Agency | L18: Vanshika V | M18: 46283 | N18: Vanshika V | P18: https://docs.google.com/document/d/1adWWq7op5vLWMCttQ1VPvc5T4dOFtTJJ/edit?usp=drive_link&ouid=101023058405307348147&rtpof=true&sd=true | Q18: https://drive.google.com/drive/folders/18PRRzh_bCalyoHm28jlcBL3s1HXZsokb?usp=drive_link | S18: Batch 1 Review
A19: Dragon Centurion | B19: Sarah Hawke | C19: High-Stakes Games & Deadly Trials (Done) | D19: https://www.goodreads.com/series/422708-dragon-centurion | E19: 687612 | F19: 4.46 | G19: 5 | H19: 1671 | I19: Indie / Self-Published | J19: New Keywords - Amazon | L19: Sakshi Saxena | P19: 1_Dragon_Centurion_Resurgence_-_Sarah_Hawke.docx | Q19: Dragon Centurion | S19: Batch 2 Review
A20: Sookie Stackhouse | B20: Charlaine Harris | C20: High Fantasy Court Adventure | D20: https://www.goodreads.com/series/42636-sookie-stackhouse | E20: 565155 | F20: 3.97 | G20: 13 | H20: 4112 | I20: ) Format: Audible Audiobook | J20: New Keywords - Amazon | L20: Sakshi Saxena | P20: 1_Dead_Until_Dark_-_Charlaine_Harris.docx | Q20: Sookie Stackhouse | S20: Batch 2 Review
A21: Chaos | B21: Fae Quin | C21: High Fantasy Court Adventure | D21: https://www.goodreads.com/series/127680-chaos | E21: 534728 | F21: 4.11 | G21: 7 | H21: 1938 | I21: Indie / Self-Published | J21: New Keywords - Amazon | L21: Sakshi Saxena | P21: 1_Soul (Farrell Claire).docx | Q21: Chaos | S21: Batch 2 Review
A22: Assistant and the Villain | B22: Hannah Nicole Maehrer | C22: Gothic Dark Romantasy | D22: https://www.goodreads.com/series/377072-assistant-to-the-villain | E22: 392049 | F22: 3.93 | G22: 4 | H22: 1446 | I22: Entangled: Red Tower Books | J22: Self-Represented / N/A | K22: Indie / Self-Published | L22: Sakshi Saxena | P22: 1_Assistant_to_the_villain_-_Hannah_Nicole_Maehrer.docx | Q22: Assistant To The Villain | S22: Batch 2 Review
A23: The Captive | B23: Erica Spiller | C23: Paranormal Romance | D23: https://www.goodreads.com/series/86676-the-captive | E23: 21690 | F23: 4.02 | G23: 8 | H23: 21690 | I23: Indie / Self-Published | J23: Metamorphosis Literary Agency | L23: Vanshika V | M23: 46283 | N23: Vanshika V | P23: https://docs.google.com/document/d/1AZ72q7C8i_7omvj052THx2y2GU2asMRf/edit?usp=drive_link&ouid=101023058405307348147&rtpof=true&sd=true | Q23: https://drive.google.com/drive/folders/1N4b9VEqoo2FBz5hKijQbMEwgVsajsyoz?usp=drive_link | S23: Batch 1 Review
A24: Kingdom of the Wicked Paperback Boxed Set | B24: Kerri Maniscalco | C24: Gothic Dark Romantasy | D24: https://www.goodreads.com/series/270202-kingdom-of-the-wicked | E24: 371413 | F24: 3.86 | G24: 3 | H24: 1226 | I24: Little, Brown Books for Young Readers | J24: Self-Represented / N/A | K24: Indie / Self-Published | L24: Sakshi Saxena | P24: 1_Kingdom_of_the_Wicked_Complete_Trilogy_-_Kerri_Maniscalco.docx | Q24: Kingdom Of The Wicked | S24: Batch 2 Review
A25: Wicked Games | B25: Kaylie Smith | C25: Gothic Dark Romantasy | D25: https://www.goodreads.com/series/400760-wicked-games | E25: 363340 | F25: 4.04 | G25: 3 | H25: 1393 | I25: Hachette UK - Second Sky | J25: Self-Represented / N/A | K25: Indie / Self-Published | L25: Sakshi Saxena | P25: 1_Phantasma_-_Kaylie_Smith.docx | Q25: Wicked Games | S25: Batch 2 Review
A26: Backstreet Evolutionist | B26: Anton Panarin | C26: High-Stakes Games & Deadly Trials (Done) | D26: https://www.goodreads.com/series/420245-backstreet-evolutionist | E26: 358860 | F26: 4.26 | G26: 7 | H26: 2455 | I26: Indie / Self-Published | J26: New Keywords - Amazon | L26: Sakshi Saxena | P26: 1_Backstreet_Evolutionist_Book_1_-_Anton_Panarin.docx | Q26: Backstreet Evolutionist | S26: Batch 2 Review
A27: Kingdom Of The White Sea | B27: Sarah M. Cradit | C27: High Fantasy Court Adventure | D27: https://www.goodreads.com/series/292339-kingdom-of-the-white-sea | E27: 803 | F27: 3.74 | G27: 3 | H27: 2083 | I27: Indie / Self-Published | J27: Metamorphosis Literary Agency | L27: Noel Regis | M27: 46282 | N27: Sakshi Saxena | O27: 46286 | P27: 1_The Kingless Crown.docx | Q27: 27_Kingdom of the White Sea | R27: Vanshika V | S27: Batch 1 Review
A28: The Black Dagger Brotherhood | B28: J. R. Ward | C28: High Fantasy Court Adventure | D28: https://www.goodreads.com/series/41963-black-dagger-brotherhood | E28: 358722 | F28: 4.15 | G28: 25 | H28: 10909 | I28: Indie / Self-Published | J28: New Keywords - Amazon | L28: Sakshi Saxena | P28: 1_Dark_Lover_Black_Dagger_Brotherhood_1_-_JR_Ward.docx | Q28: Black Dagger Brotherhood | S28: Batch 2 Review
A29: The Others | B29: Annie Smith | C29: Werewolf / Shifter Romance | D29: https://www.goodreads.com/series/99557-the-others | E29: 65629 | F29: 4.25 | G29: 10 | H29: 65629 | I29: Indie / Self-Published | J29: Jane Rotrosen Agency | L29: Vanshika V | M29: 46283 | N29: Vanshika V | P29: https://docs.google.com/document/d/12wZLqtIre7YvQctzS7xuAqT-CWOjX2GN/edit?usp=drive_link&ouid=101023058405307348147&rtpof=true&sd=true | Q29: https://drive.google.com/drive/folders/1_up8L0uC7UerTxoII-taECBEt7OvsSrC?usp=drive_link | S29: Batch 1 Review
A30: Blood And Ash World Reading Order | B30: Asha Lemmie | C30: High Fantasy Court Adventure | D30: https://www.goodreads.com/series/426746-blood-and-ash-world-reading-order | E30: 897900 | F30: 4.21 | G30: 11 | H30: 897900 | I30: Indie / Self-Published | J30: Jane Rotrosen Agency | L30: Vanshika V | M30: 46283 | N30: Vanshika V | P30: https://docs.google.com/document/d/135ekbg0UiYUSyVy8jO6tQ5AlJfQuRkV8/edit?usp=drive_link&ouid=101023058405307348147&rtpof=true&sd=true | Q30: https://drive.google.com/drive/folders/15Lw_RHugBnrWsrOGJ7oRPjcoMipkUPbM?usp=drive_link | S30: Batch 1 Review
A31: Serpent & Dove | B31: Shelby Mahurin | C31: Urban Coven Romance | D31: https://www.goodreads.com/series/253800-serpent-dove | E31: 353073 | F31: 3.96 | G31: 3 | H31: 1673 | I31: HarperCollins | J31: New Keywords - Amazon | L31: Sakshi Saxena | P31: 1_Serpent_n_Dove_-_Shelby_Mahurin.docx | Q31: Serpent Dove | S31: Batch 2 Review
A32: Rogues of the Crosslands Book 1 of 2: Rogues of the Crosslands | B32: by Brenda Trim | C32: Paranormal Romance ( Done ) | D32: https://www.goodreads.com/series/343601-twisted-sisters-midlife-maelstrom | E32: 316792 | F32: 4.42 | G32: 15 | H32: 3519 | I32: Amazon.com Services LLC Additional items, like pre-orders, may be ordered individually Items included | J32: New Keywords - Amazon | L32: Sakshi Saxena | P32: 1_Packing_Serious_Magical_Mojo_-_Brenda_Trim.docx | Q32: Twisted Sisters Midlife Maelstrom | S32: Batch 2 Review
A33: The Roots Of Chaos | B33: Shannon Iwanski | C33: High Fantasy Court Adventure | D33: https://www.goodreads.com/series/341670-the-roots-of-chaos | E33: 296756 | F33: 4.16 | G33: 3 | H33: 1992 | I33: Indie / Self-Published | J33: Metamorphosis Literary Agency | L33: Sakshi Saxena | P33: 1_The_Priory_of_the_Orange_Tree_-_Samantha_Shannon.docx | Q33: The Roots of Chaos | S33: Batch 2 Review
A34: Ravenhood Legacy Trilogy | B34: Curtiss Ann Matlock | C34: High Fantasy Court Adventure | D34: https://www.goodreads.com/series/372640-ravenhood-legacy-trilogy | E34: 60193 | F34: 4.52 | G34: 3 | H34: 60193 | I34: Indie / Self-Published | J34: Jane Rotrosen Agency | L34: Vanshika V | M34: 46283 | N34: Vanshika V | P34: https://docs.google.com/document/d/1YkcNeT5boR5hp_Lr3OKZQHp-7p4a93vS/edit?usp=drive_link&ouid=101023058405307348147&rtpof=true&sd=true | Q34: https://drive.google.com/drive/folders/1WZJ1zyPhIBhPxS9GBC-1smJcFWeK30hX?usp=drive_link | S34: Batch 1 Review
A35: The selection | B35: Kiera Cass | C35: High Fantasy Court Adventure | D35: https://www.goodreads.com/series/57517-the-selection | E35: 264382 | F35: 4.07 | G35: 5 | H35: 1615 | I35: Indie / Self-Published | J35: New Keywords - Amazon | L35: Sakshi Saxena | P35: 1_The_Selection_1_-_Kiera_Cass.docx | Q35: The Selection | S35: Batch 2 Review
A36: The Iron Fey | B36: Julie Garwood | C36: High Fantasy Court Adventure | D36: https://www.goodreads.com/series/47329-the-iron-fey | E36: 219403 | F36: 3.87 | G36: 10 | H36: 219403 | I36: Indie / Self-Published | J36: Jane Rotrosen Agency | L36: Vanshika V | M36: 46283 | N36: Vanshika V | P36: https://docs.google.com/document/d/1YafY33HU-RojH2WvpBBn-RiwK9oDIvKe/edit?usp=drive_link&ouid=101023058405307348147&rtpof=true&sd=true | Q36: https://drive.google.com/drive/folders/1YjJfGoDVMlRhji1WdLfrqE4lTkwqkVw0?usp=drive_link | S36: Batch 1 Review
A37: Emily Wilde's History of Dark Faerie: A Novel | B37: Heather Fawcett | C37: High Fantasy Court Adventure | D37: https://www.goodreads.com/series/353912-emily-wilde | E37: 235404 | F37: 3.95 | G37: 4 | H37: 1458 | I37: Del Rey | J37: Self-Represented / N/A | K37: Indie / Self-Published | L37: Sakshi Saxena | P37: 1_Emily_Wildes_Encyclopaedia_of_Faeries_-_Heather_Fawcett.docx | Q37: Emily Wilde | S37: Batch 2 Review
A38: Reign Of Remnants | B38: Julie Johnson | C38: High-Stakes Games & Deadly Trials | D38: https://www.goodreads.com/series/397346-reign-of-remnants | E38: 13147 | F38: 3.93 | G38: 3 | H38: 1088 | I38: Indie / Self-Published | J38: Jane Rotrosen Agency | L38: Noel Regis | M38: 46282 | N38: Sakshi Saxena | O38: 46286 | P38: 1_The Wind Weaver.docx | Q38: 38_Reign of Remnants | R38: Vanshika V | S38: Batch 1 Review
A39: The Marionettes | B39: Katie Lynch | C39: Paranormal Romance | D39: https://www.goodreads.com/series/320243-the-marionettes | E39: 9696 | F39: 3.88 | G39: 4 | H39: 9696 | I39: Indie / Self-Published | J39: Jane Rotrosen Agency | L39: Vanshika V | M39: 46283 | N39: Vanshika V | P39: https://docs.google.com/document/d/1prG7-cor9WE9I-H8dKnBTomzoCU8YK-t/edit?usp=drive_link&ouid=101023058405307348147&rtpof=true&sd=true | Q39: https://drive.google.com/drive/folders/1jFopVdx_P4ISQ_xIB2AUTJI0l0vNy03X?usp=drive_link | S39: Batch 1 Review
A40: Blood of the Ancients | B40: Dan Michaelson | C40: High-Stakes Games & Deadly Trials (Done) | D40: https://www.goodreads.com/series/345894-blood-of-the-ancients | E40: 230469 | F40: 4.06 | G40: 13 | H40: 3553 | I40: Indie / Self-Published | J40: New Keywords - Amazon | L40: Sakshi Saxena | P40: 1_Dragon_Forged_-_Dan_Michaelson.docx | Q40: Blood of the Ancients | S40: Batch 2 Review
...

Sheet Books not found
A1: Series Name | B1: Missing Book Numbers | C1: Goodreads Series Link | D1: POC | E1: Date | F1: Status
A2: Akora | B2: All Books (1–5) | C2: https://www.goodreads.com/series/43414-akora | D2: Sakshi Saxena | E2: 46281 | F2: Done
A3: Rubyverse Reading Order | B3: All Books (1–5) | C3: https://www.goodreads.com/series/434234-rubyverse-reading-order | D3: Sakshi Saxena | E3: 46281 | F3: Done
A4: Shifter Nation Box Sets | B4: All Books (1–5) | C4: https://www.goodreads.com/series/234894-shifter-nation-box-sets | D4: Sakshi Saxena | E4: 46281 | F4: Done
A5: Agnyeoreul Jugyeo Jwo Comic | B5: All Books (1–5) | C5: https://www.goodreads.com/series/336854-agnyeoreul-jugyeo-jwo-comic | D5: Sakshi Saxena | E5: 46281 | F5: Korea
A6: Futsutsuka Na Akujo Dewa Gozaimasu Ga Suug | B6: All Books (1–5) | C6: https://www.goodreads.com/series/356817-futsutsuka-na-akujo-dewa-gozaimasu-ga-suug | D6: Sakshi Saxena | E6: 46281 | F6: Done
A7: House Of Quercus | B7: All Books (1–5) | C7: https://www.goodreads.com/series/247507-house-of-quercus | D7: Sakshi Saxena | E7: 46281 | F7: Done
A8: No Kemono | B8: All Books (1–5) | C8: https://www.goodreads.com/series/293898-no-kemono | D8: Sakshi Saxena | E8: 46281 | F8: Done
A9: Tensei Akujo No Kuro Rekishi | B9: All Books (1–5) | C9: https://www.goodreads.com/series/300963-tensei-akujo-no-kuro-rekishi | D9: Sakshi Saxena | E9: 46281 | F9: Korea
A10: Tensei Oujo Wa Kyou Mo Hata O Tatakioru Novel | B10: All Books (1–5) | C10: https://www.goodreads.com/series/249669-tensei-oujo-wa-kyou-mo-hata-o-tatakioru-novel | D10: Sakshi Saxena | E10: 46281 | F10: Korea
A11: Villains | B11: Book 1 | C11: https://www.goodreads.com/series/162322-villains | D11: Sakshi Saxena | E11: 46281 | F11: Done
A12: Chaos Magic | B12: Book 1 | C12: https://www.goodreads.com/series/365832-chaos-magic | D12: Sakshi Saxena | E12: 46281 | F12: Done
A13: The Protectors | B13: Book 1, Book 2 | C13: https://www.goodreads.com/series/197556-the-protectors | D13: Sakshi Saxena | E13: 46281 | F13: Done
... A17: Pledged To Him | B17: Book 1, Book 5 | C17: https://www.goodreads.com/series/446204-pledged-to-him | D17: Sakshi Saxena | E17: 46281 | F17: Done
A18: The Shadowhunter Chronicles | B18: Book 3, Book 4 | C18: {=_xlfn.XLOOKUP(A18,'Picks for Review (Sep 26)'!A:A,'Picks for Review (Sep 26)'!D:D)} | D18: Anushka Baisya | E18: 46281 | F18: Missing (Book 3, Book 4)
A19: Kingdom Of The Wicked | B19: Book 4 | C19: {=_xlfn.XLOOKUP(A19,'Picks for Review (Sep 26)'!A:A,'Picks for Review (Sep 26)'!D:D)} | D19: Anushka Baisya | E19: 46281 | F19: Missing (Book 4)
A20: Serpent Dove | B20: Book 4, Book 5 | C20: {=_xlfn.XLOOKUP(A20,'Picks for Review (Sep 26)'!A:A,'Picks for Review (Sep 26)'!D:D)} | D20: Anushka Baisya | E20: 46281 | F20: Missing (Book 4, Book 5)
A21: The Roots Of Chaos | B21: Book 3, Book 4 | C21: {=_xlfn.XLOOKUP(A21,'Picks for Review (Sep 26)'!A:A,'Picks for Review (Sep 26)'!D:D)} | D21: Anushka Baisya | E21: 46281 | F21: Missing (Book 3, Book 4)
A22: Emily Wilde | B22: Book 4, Book 5 | C22: {=_xlfn.XLOOKUP(A22,'Picks for Review (Sep 26)'!A:A,'Picks for Review (Sep 26)'!D:D)} | D22: Anushka Baisya | E22: 46281 | F22: Missing (Book 4, Book 5)
A23: Avalon Publication Order | B23: Book 1, Book 2, Book 3, Book 4, Book 5 | C23: {=_xlfn.XLOOKUP(A23,'Picks for Review (Sep 26)'!A:A,'Picks for Review (Sep 26)'!D:D)} | D23: Anushka Baisya | E23: 46281 | F23: Missing (Book 1, Book 2, Book 3, Book 4, Book 5) | G23: No Links
A24: Villains Of Lore | B24: Book 3, Book 4, Book 5 | C24: {=_xlfn.XLOOKUP(A24,'Picks for Review (Sep 26)'!A:A,'Picks for Review (Sep 26)'!D:D)} | D24: Anushka Baisya | E24: 46281 | F24: Missing (Book 3, Book 4, Book 5) | G24: Till Book 3 is available on goodreads
A25: The Chronicles Of Ixia | B25: Book 4 | C25: {=_xlfn.XLOOKUP(A25,'Picks for Review (Sep 26)'!A:A,'Picks for Review (Sep 26)'!D:D)} | D25: Anushka Baisya | E25: 46281 | F25: Missing (Book 4) | G25: Updated
A26: The Shadow Walkers Saga | B26: Book 3 | C26: {=_xlfn.XLOOKUP(A26,'Picks for Review (Sep 26)'!A:A,'Picks for Review (Sep 26)'!D:D)} | D26: Anushka Baisya | E26: 46281 | F26: Missing (Book 3) | G26: Updated
A27: The Daevabad Trilogy | B27: Book 4, Book 5 | C27: {=_xlfn.XLOOKUP(A27,'Picks for Review (Sep 26)'!A:A,'Picks for Review (Sep 26)'!D:D)} | D27: Anushka Baisya | E27: 46281 | F27: Missing (Book 4, Book 5) | G27: Till Book 3 is available on goodreads
A28: The Eating Woods | B28: Book 3, Book 4, Book 5 | C28: {=_xlfn.XLOOKUP(A28,'Picks for Review (Sep 26)'!A:A,'Picks for Review (Sep 26)'!D:D)} | D28: Anushka Baisya | E28: 46281 | F28: Missing (Book 3, Book 4, Book 5) | G28: Till Book 3 is available on goodreads ; not able to find book 3
A29: Dark Prince Road | B29: Book 4, Book 5 | C29: {=_xlfn.XLOOKUP(A29,'Picks for Review (Sep 26)'!A:A,'Picks for Review (Sep 26)'!D:D)} | D29: Anushka Baisya | E29: 46281 | F29: Missing (Book 4, Book 5) | G29: Till Book 3 is available on goodreads
A30: Bloodwing Academy | B30: Book 4, Book 5 | C30: {=_xlfn.XLOOKUP(A30,'Picks for Review (Sep 26)'!A:A,'Picks for Review (Sep 26)'!D:D)} | D30: Anushka Baisya | E30: 46281 | F30: Missing (Book 4, Book 5) | G30: Till Book 3 is available on goodreads
A31: These Hollow Vows | B31: Book 3, Book 5 | C31: {=_xlfn.XLOOKUP(A31,'Picks for Review (Sep 26)'!A:A,'Picks for Review (Sep 26)'!D:D)} | D31: Anushka Baisya | E31: 46281 | F31: Missing (Book 3, Book 5) | G31: Till Book 4 is available on goodreads
A32: Inheritance Trilogy | B32: Book 4 | C32: {=_xlfn.XLOOKUP(A32,'Picks for Review (Sep 26)'!A:A,'Picks for Review (Sep 26)'!D:D)} | D32: Anushka Baisya | E32: 46281 | F32: Missing (Book 4)
A33: Monsters Muses | B33: Book 4 | C33: {=_xlfn.XLOOKUP(A33,'Picks for Review (Sep 26)'!A:A,'Picks for Review (Sep 26)'!D:D)} | D33: Anushka Baisya | E33: 46281 | F33: Missing (Book 4)
A34: Underworld Saga | B34: Book 5 | C34: {=_xlfn.XLOOKUP(A34,'Picks for Review (Sep 26)'!A:A,'Picks for Review (Sep 26)'!D:D)} | D34: Anushka Baisya | E34: 46281 | F34: Missing (Book 5)
A35: The Wolves Of Ruin | B35: Book 3, Book 4 | C35: {=_xlfn.XLOOKUP(A35,'Picks for Review (Sep 26)'!A:A,'Picks for Review (Sep 26)'!D:D)} | D35: Anushka Baisya | E35: 46281 | F35: Missing (Book 3, Book 4) | G35: Till Book 3 is available on goodreads ; not able to find book 3
A36: Fae Kings Of Eden | B36: Book 5 | C36: {=_xlfn.XLOOKUP(A36,'Picks for Review (Sep 26)'!A:A,'Picks for Review (Sep 26)'!D:D)} | D36: Anushka Baisya | E36: 46281 | F36: Missing (Book 5) | G36: Till Book 4 is available on goodreads
A37: The Treasure Of Paragon | B37: Book 5 | C37: {=_xlfn.XLOOKUP(A37,'Picks for Review (Sep 26)'!A:A,'Picks for Review (Sep 26)'!D:D)} | D37: Anushka Baisya | E37: 46281 | F37: Missing (Book 5) | G37: updated
A38: Thorne Hill | B38: Book 2, Book 3, Book 4 | C38: {=_xlfn.XLOOKUP(A38,'Picks for Review (Sep 26)'!A:A,'Picks for Review (Sep 26)'!D:D)} | D38: Anushka Baisya | E38: 46281 | F38: Missing (Book 2, Book 3, Book 4)
A39: The Tether Trilogy | B39: Book 4, Book 5 | C39: {=_xlfn.XLOOKUP(A39,'Picks for Review (Sep 26)'!A:A,'Picks for Review (Sep 26)'!D:D)} | D39: Anushka Baisya | E39: 46281 | F39: Missing (Book 4, Book 5) | G39: Till Book 3 is available on goodreads
A40: Boston Uncommon | B40: Book 4, Book 5 | C40: {=_xlfn.XLOOKUP(A40,'Picks for Review (Sep 26)'!A:A,'Picks for Review (Sep 26)'!D:D)} | D40: Anushka Baisya | E40: 46281 | F40: Missing (Book 4, Book 5) | G40: updated
A41: Love And Light | B41: Book 2, Book 5 | C41: {=_xlfn.XLOOKUP(A41,'Picks for Review (Sep 26)'!A:A,'Picks for Review (Sep 26)'!D:D)} | D41: Anushka Baisya | E41: 46281 | F41: Missing (Book 2, Book 5) | G41: updated
A42: Grizzlies Gone Wild | B42: Book 3, Book 4, Book 5 | C42: {=_xlfn.XLOOKUP(A42,'Picks for Review (Sep 26)'!A:A,'Picks for Review (Sep 26)'!D:D)} | D42: Anushka Baisya | E42: 46281 | F42: Missing (Book 3, Book 4, Book 5) | G42: updated
A43: Kings Of Avalier | B43: Book 5 | C43: {=_xlfn.XLOOKUP(A43,'Picks for Review (Sep 26)'!A:A,'Picks for Review (Sep 26)'!D:D)} | D43: Anushka Baisya | E43: 46281 | F43: Missing (Book 5) | G43: Till Book 4 is available on goodreads
...

Sheet Batch 1 - 229
A1: Series Name | B1: Author | C1: Sub-Genre | D1: Book Series (GoodReads URL) | E1: GoodReads No. of Ratings | F1: Goodreads Book 1 Ratings | G1: Total Primary Books | H1: Total primary Books Page Count | I1: Imprint / Publisher - Book | J1: Agencies | K1: Imprint / Publisher - Audiobook | L1: Crawling POC | M1: Crawling Date | N1: Links addition POC | O1: Links Date | P1: Book 1 Link | Q1: Books (1 - 5) Links
A2: Green Creek | B2: Kelly Bennett | C2: Paranormal Romance | D2: https://www.goodreads.com/series/206510-green-creek | E2: 118376 | F2: 4.18 | G2: 4 | H2: 118376 | I2: Indie / Self-Published | J2: Metamorphosis Literary Agency | L2: Vanshika V | M2: 46283 | N2: Vanshika V | P2: https://docs.google.com/document/d/102Co9URvI7NHwz65ofheImstJmx3_C2w/edit?usp=drive_link&ouid=101023058405307348147&rtpof=true&sd=true | Q2: https://drive.google.com/drive/folders/15WyC66FwRnei2POYs01P4BHDFr_5dLPr?usp=drive_link
A3: Air Awakens | B3: Elise Fender Burns | C3: High Fantasy Court Adventure | D3: https://www.goodreads.com/series/155275-air-awakens | E3: 63472 | F3: 3.97 | G3: 5 | H3: 63472 | I3: Indie / Self-Published | J3: Metamorphosis Literary Agency | L3: Vanshika V | M3: 46283 | N3: Vanshika V | P3: https://docs.google.com/document/d/1a42Nqridsbx5sLJgnfsjtz_tM0HKN4Lm/edit?usp=drive_link&ouid=101023058405307348147&rtpof=true&sd=true | Q3: https://drive.google.com/drive/folders/1Z8o5jSlW3Bq8CpAyuYG0Opo3jnRKwAqb?usp=drive_link
A4: Warrior Security | B4: Brittany Cooper | C4: High-Stakes Games & Deadly Trials | D4: https://www.goodreads.com/series/426999-warrior-security | E4: 2310 | F4: 4.47 | G4: 5 | H4: 2310 | I4: Indie / Self-Published | J4: Metamorphosis Literary Agency | L4: Vanshika V | M4: 46283 | N4: Vanshika V | P4: https://docs.google.com/document/d/1uGe-oUialP2el1Y3fhEazOkMe1ixL1Sf/edit?usp=drive_link&ouid=101023058405307348147&rtpof=true&sd=true | Q4: https://drive.google.com/drive/folders/1GRRhk2RsoERxTDphHtU0G_6kKP5UTafA?usp=drive_link
A5: Fire And Fang | B5: Lindsay Flanagan | C5: High Fantasy Court Adventure | D5: https://www.goodreads.com/series/428113-fire-and-fang | E5: 3087 | F5: 4.07 | G5: 5 | H5: 3087 | I5: Indie / Self-Published | J5: Metamorphosis Literary Agency | L5: Vanshika V | M5: 46283 | N5: Vanshika V | P5: https://docs.google.com/document/d/1pDpQYoA6iNGrpTRf35YkQ72AulEuFaRE/edit?usp=drive_link&ouid=101023058405307348147&rtpof=true&sd=true | Q5: https://drive.google.com/drive/folders/11Ac4Iz28Vn5AQpHld3YGDFg2606IfaR6?usp=drive_link
A6: Shatter Me | B6: Tahereh Mafi | C6: Paranormal Romance | D6: https://www.goodreads.com/series/65730-shatter-me | E6: 1260128 | F6: 3.84 | G6: 12 | H6: 2481 | I6: Storytide | K6: Storytide | L6: Noel Regis | M6: 46282 | P6: 1_Shatter Me.docx | Q6: 11_Shatter Me
A7: This Woven Kingdom | B7: Tiffany W. Killoren | C7: Mythology, Legend & Fairy Tale Retelling | D7: https://www.goodreads.com/series/319224-this-woven-kingdom | E7: 119741 | F7: 4.28 | G7: 5 | H7: 119741 | I7: Indie / Self-Published | J7: Metamorphosis Literary Agency | L7: Vanshika V | M7: 46283 | N7: Vanshika V | P7: https://docs.google.com/document/d/1wxQ6oyhK93uhZ1Vu_KLr2C3GVXtcOz_k/edit?usp=drive_link&ouid=101023058405307348147&rtpof=true&sd=true | Q7: https://drive.google.com/drive/folders/11ZUWyaB1f9-L9YCg_WmD7oXTFWU3wwEU?usp=drive_link
A8: Tiffany Black Mysteries | B8: Tiffany W. Killoren | C8: Cozy / Cottagecore Romantasy | D8: https://www.goodreads.com/series/124119-tiffany-black-mysteries | E8: 10545 | F8: 3.71 | G8: 37 | H8: 10545 | I8: Indie / Self-Published | J8: Metamorphosis Literary Agency | L8: Vanshika V | M8: 46283 | N8: Vanshika V | P8: https://docs.google.com/document/d/1ALVv-mpE7V69_4xV4EZZQBBOL08me4xH/edit?usp=drive_link&ouid=101023058405307348147&rtpof=true&sd=true | Q8: https://drive.google.com/drive/folders/1mH43uDPXFbMxk1g9WCgnxqnt-IJgjqmS?usp=drive_link
A9: Arcane Society | B9: Mike Krentz | C9: Paranormal Romance | D9: https://www.goodreads.com/series/57569-arcane-society | E9: 16119 | F9: 3.91 | G9: 12 | H9: 16119 | I9: Indie / Self-Published | J9: Metamorphosis Literary Agency | L9: Vanshika V | M9: 46283 | N9: Vanshika V | P9: https://docs.google.com/document/d/1WKhrsKagyScv3YdVnxwWaAPu3H37_vc6/edit?usp=drive_link&ouid=101023058405307348147&rtpof=true&sd=true | Q9: https://drive.google.com/drive/folders/1BCNS4Cq-JEWdGzXyBnoiW81CzBAbnWoS?usp=drive_link
A10: Fae & Alchemy | B10: Callie Hart | C10: High Fantasy Court Adventure | D10: https://www.goodreads.com/series/392242-fae-alchemy | E10: 987885 | F10: 4.3 | G10: 4 | H10: 3216 | I10: Podium Audio | J10: New Keywords - Amazon | L10: Noel Regis | M10: 46282 | P10: 1_Quicksilver_-_Callie_Hart.docx | Q10: Fae & Alchemy Series
A11: Red Rising | B11: Pierce Brown | C11: Paranormal Romance | D11: https://www.goodreads.com/series/117100-red-rising-saga | E11: 853673 | F11: 4.27 | G11: 18 | H11: 8359 | I11: Recorded Books | K11: Recorded Books | L11: Noel Regis | M11: 46282 | N11: Sakshi Saxena | O11: 46286 | P11: 1_Red Rising.docx | Q11: 17_Red Rising Saga by Pierce Brown
A12: The Witchlands | B12: Kathy MacMillan | C12: High Fantasy Court Adventure | D12: https://www.goodreads.com/series/124183-the-witchlands | E12: 53820 | F12: 3.84 | G12: 5 | H12: 53820 | I12: Indie / Self-Published | J12: Metamorphosis Literary Agency | L12: Vanshika V | M12: 46283 | N12: Vanshika V | P12: https://docs.google.com/document/d/1adWWq7op5vLWMCttQ1VPvc5T4dOFtTJJ/edit?usp=drive_link&ouid=101023058405307348147&rtpof=true&sd=true | Q12: https://drive.google.com/drive/folders/18PRRzh_bCalyoHm28jlcBL3s1HXZsokb?usp=drive_link
A13: The Captive | B13: Erica Spiller | C13: Paranormal Romance | D13: https://www.goodreads.com/series/86676-the-captive | E13: 21690 | F13: 4.02 | G13: 8 | H13: 21690 | I13: Indie / Self-Published | J13: Metamorphosis Literary Agency | L13: Vanshika V | M13: 46283 | N13: Vanshika V | P13: https://docs.google.com/document/d/1AZ72q7C8i_7omvj052THx2y2GU2asMRf/edit?usp=drive_link&ouid=101023058405307348147&rtpof=true&sd=true | Q13: https://drive.google.com/drive/folders/1N4b9VEqoo2FBz5hKijQbMEwgVsajsyoz?usp=drive_link
A14: The Others | B14: Annie Smith | C14: Werewolf / Shifter Romance | D14: https://www.goodreads.com/series/99557-the-others | E14: 65629 | F14: 4.25 | G14: 10 | H14: 65629 | I14: Indie / Self-Published | J14: Jane Rotrosen Agency | L14: Vanshika V | M14: 46283 | N14: Vanshika V | P14: https://docs.google.com/document/d/12wZLqtIre7YvQctzS7xuAqT-CWOjX2GN/edit?usp=drive_link&ouid=101023058405307348147&rtpof=true&sd=true | Q14: https://drive.google.com/drive/folders/1_up8L0uC7UerTxoII-taECBEt7OvsSrC?usp=drive_link
A15: Blood And Ash World Reading Order | B15: Asha Lemmie | C15: High Fantasy Court Adventure | D15: https://www.goodreads.com/series/426746-blood-and-ash-world-reading-order | E15: 897900 | F15: 4.21 | G15: 11 | H15: 897900 | I15: Indie / Self-Published | J15: Jane Rotrosen Agency | L15: Vanshika V | M15: 46283 | N15: Vanshika V | P15: https://docs.google.com/document/d/135ekbg0UiYUSyVy8jO6tQ5AlJfQuRkV8/edit?usp=drive_link&ouid=101023058405307348147&rtpof=true&sd=true | Q15: https://drive.google.com/drive/folders/15Lw_RHugBnrWsrOGJ7oRPjcoMipkUPbM?usp=drive_link
A16: Ravenhood Legacy Trilogy | B16: Curtiss Ann Matlock | C16: High Fantasy Court Adventure | D16: https://www.goodreads.com/series/372640-ravenhood-legacy-trilogy | E16: 60193 | F16: 4.52 | G16: 3 | H16: 60193 | I16: Indie / Self-Published | J16: Jane Rotrosen Agency | L16: Vanshika V | M16: 46283 | N16: Vanshika V | P16: https://docs.google.com/document/d/1YkcNeT5boR5hp_Lr3OKZQHp-7p4a93vS/edit?usp=drive_link&ouid=101023058405307348147&rtpof=true&sd=true | Q16: https://drive.google.com/drive/folders/1WZJ1zyPhIBhPxS9GBC-1smJcFWeK30hX?usp=drive_link
A17: The Iron Fey | B17: Julie Garwood | C17: High Fantasy Court Adventure | D17: https://www.goodreads.com/series/47329-the-iron-fey | E17: 219403 | F17: 3.87 | G17: 10 | H17: 219403 | I17: Indie / Self-Published | J17: Jane Rotrosen Agency | L17: Vanshika V | M17: 46283 | N17: Vanshika V | P17: https://docs.google.com/document/d/1YafY33HU-RojH2WvpBBn-RiwK9oDIvKe/edit?usp=drive_link&ouid=101023058405307348147&rtpof=true&sd=true | Q17: https://drive.google.com/drive/folders/1YjJfGoDVMlRhji1WdLfrqE4lTkwqkVw0?usp=drive_link
A18: The Marionettes | B18: Katie Lynch | C18: Paranormal Romance | D18: https://www.goodreads.com/series/320243-the-marionettes | E18: 9696 | F18: 3.88 | G18: 4 | H18: 9696 | I18: Indie / Self-Published | J18: Jane Rotrosen Agency | L18: Vanshika V | M18: 46283 | N18: Vanshika V | P18: https://docs.google.com/document/d/1prG7-cor9WE9I-H8dKnBTomzoCU8YK-t/edit?usp=drive_link&ouid=101023058405307348147&rtpof=true&sd=true | Q18: https://drive.google.com/drive/folders/1jFopVdx_P4ISQ_xIB2AUTJI0l0vNy03X?usp=drive_link
A19: Cassandra Palmer | B19: Matthew Palmer | C19: Urban / Contemporary Fantasy Romance | D19: https://www.goodreads.com/series/49237-cassandra-palmer | E19: 37083 | F19: 3.72 | G19: 14 | H19: 37083 | I19: Indie / Self-Published | J19: Jane Rotrosen Agency | L19: Vanshika V | M19: 46283 | N19: Vanshika V | P19: https://docs.google.com/document/d/1E8h2XWibVtYByhgI5qhzIFNRJMz2p55X/edit?usp=drive_link&ouid=101023058405307348147&rtpof=true&sd=true | Q19: https://drive.google.com/drive/folders/1WZ1OLSkrK9l-rWgXg6Hx7YzLEyKMLhSz?usp=drive_link
A20: Meg Langslow | B20: Meg Shaffer | C20: Cozy / Cottagecore Romantasy | D20: https://www.goodreads.com/series/41805-meg-langslow | E20: 14392 | F20: 3.89 | G20: 41 | H20: 14392 | I20: Indie / Self-Published | J20: Jane Rotrosen Agency | L20: Vanshika V | M20: 46283 | N20: Vanshika V | P20: https://docs.google.com/document/d/1KyUk6Z2rCFSa20m2bM2ayySgkswWdYw0/edit?usp=drive_link&ouid=101023058405307348147&rtpof=true&sd=true | Q20: https://drive.google.com/drive/folders/1jAYGNYCy4bjjfdMkmc6J--mysTfXq5GF?usp=drive_link
A21: 1 800 Where R You | B21: Meg Shaffer | C21: Paranormal Romance | D21: https://www.goodreads.com/series/40569-1-800-where-r-you | E21: 17799 | F21: 4.05 | G21: 7 | H21: 17799 | I21: Indie / Self-Published | J21: Jane Rotrosen Agency | L21: Vanshika V | M21: 46283 | N21: Vanshika V | P21: https://docs.google.com/document/d/1a_DBroEYhDYUZZ_9pA2J-tEKP-7lpp7b/edit?usp=drive_link&ouid=101023058405307348147&rtpof=true&sd=true | Q21: https://drive.google.com/drive/folders/1ORWEGkxAzBEPEiIJ5U7D_jACG9kTicZD?usp=drive_link
A22: Aunt Dimity Mystery | B22: Nancy Atherton | C22: Cozy / Cottagecore Romantasy | D22: https://www.goodreads.com/series/42315-aunt-dimity-mystery | E22: 15716 | F22: 3.95 | G22: 25 | H22: 15716 | I22: Indie / Self-Published | J22: Jane Rotrosen Agency | L22: Vanshika V | M22: 46283 | N22: Vanshika V | P22: https://docs.google.com/document/d/1k537Q7hk_uLa8koJCiopQKCD7n0VZVvU/edit?usp=drive_link&ouid=101023058405307348147&rtpof=true&sd=true | Q22: https://drive.google.com/drive/folders/1t2XtLfUaXUijVJvATgs_M6fbj1ClrCxB?usp=drive_link
A23: Goddess Summoning | B23: PC Cast | C23: Mythology, Legend & Fairy Tale Retelling | D23: https://www.goodreads.com/series/40627-goddess-summoning | E23: 12053 | F23: 3.84 | G23: 7 | H23: 12053 | I23: Indie / Self-Published | J23: Jane Rotrosen Agency | L23: Vanshika V | M23: 46283 | N23: Vanshika V | P23: https://docs.google.com/document/d/1m5ddGHE0oC5Yhr-UlhC-AyhhskRA7LT0/edit?usp=drive_link&ouid=101023058405307348147&rtpof=true&sd=true | Q23: https://drive.google.com/drive/folders/1egk-g5YU6w5PXma37P3eAij3X2xp5NLa?usp=drive_link
... A29: Sweet | B29: Wendy Francis | C29: Paranormal Romance | D29: https://www.goodreads.com/series/83847-sweet | E29: 78102 | F29: 4.07 | G29: 4 | H29: 78102 | I29: Indie / Self-Published | J29: Jane Rotrosen Agency | L29: Vanshika V | M29: 46283 | N29: Vanshika V | P29: https://docs.google.com/document/d/1cLsmb1DanTTriXKLm_yIc0RdsGv0hukn/edit?usp=drive_link&ouid=101023058405307348147&rtpof=true&sd=true | Q29: https://drive.google.com/drive/folders/1A9PP1ZXzw2XKdTQG6BJbBKozIKwMrqdv?usp=drive_link
A30: Dark Verse | B30: RuNyx | C30: Gothic Dark Romantasy | D30: https://www.goodreads.com/series/287221-dark-verse | E30: 146216 | F30: 3.97 | G30: 7 | H30: 4312 | I30: P1: Amazon Digital Services | P2: Smashwords | K30: Podium Audio | L30: Noel Regis | M30: 46282 | N30: Sakshi Saxena | O30: 46286 | P30: 1_The Predator.docx | Q30: 62_Dark Verse
A31: Bloodwing Academy | B31: Briar Boleyn | C31: Gothic Dark Romantasy | D31: https://www.goodreads.com/series/390267-bloodwing-academy | E31: 127131 | F31: 3.91 | G31: 3 | H31: 1418 | I31: Podium Audio | J31: Self-Represented / N/A | K31: Podium Audio | L31: Noel Regis | M31: 46282 | N31: Sakshi Saxena | O31: 46286 | P31: 1_On Wings of Blood.docx | Q31: 67_Bloodwing Academy
A32: Crave | B32: Tracy Wolff | C32: Mythology, Legend & Fairy Tale Retelling | D32: https://www.goodreads.com/series/286781-crave | E32: 119076 | F32: 3.76 | G32: 21 | H32: 11803 | I32: Entangled Publishing | K32: Tantor Media | L32: Noel Regis | M32: 46282 | N32: Sakshi Saxena | O32: 46286 | P32: 1_Crave.docx | Q32: 71_Crave
A33: Perfectly Imperfect | B33: Neva Altaj | C33: Urban / Contemporary Fantasy Romance | D33: https://www.goodreads.com/series/343844-perfectly-imperfect | E33: 118006 | F33: 3.73 | G33: 13 | H33: 4497 | I33: Neva Altaj | K33: Podium Audio | L33: Noel Regis | M33: 46282 | N33: Sakshi Saxena | O33: 46286 | P33: 1_Painted Scars.docx | Q33: 72_Perfectly Imperfect
A34: Covenant Series | B34: Jennifer L. Armentrout | C34: Mythology, Legend & Fairy Tale Retelling | D34: https://www.goodreads.com/series/53954-covenant | E34: 116532 | F34: 4.06 | G34: 5 | H34: 1580 | I34: Self Published | K34: Tantor Media | L34: Noel Regis | M34: 46282 | N34: Sakshi Saxena | O34: 46286 | P34: 1_Half-Blood.docx | Q34: 73_Covenant
A35: Alliance | B35: S.J. Tilly | C35: Urban / Contemporary Fantasy Romance | D35: https://www.goodreads.com/series/362029-alliance | E35: 95274 | F35: 3.81 | G35: 4 | H35: 1668 | I35: Amazon Digital Services | K35: Podium Audio | L35: Noel Regis | M35: 46282 | N35: Sakshi Saxena | O35: 46286 | P35: 1_Nero.docx | Q35: 78_Alliance
A36: The Dark Elements | B36: Jennifer L. Armentrout | C36: Gothic Dark Romantasy | D36: https://www.goodreads.com/series/98903-the-dark-elements | E36: 91654 | F36: 4.16 | G36: 3 | H36: 1219 | I36: Tantor Audio | J36: Self-Represented / N/A | K36: Tantor Media | L36: Noel Regis | M36: 46282 | N36: Sakshi Saxena | O36: 46286 | P36: 1_White Hot Kiss.docx | Q36: 79_The Dark Elements
A37: Damaged Souls: A Reverse Harem Fantasy Romance (Saints Academy Book 2) | B37: Kayla Edwards | C37: Modern Low Fantasy | D37: https://www.goodreads.com/series/335398-house-of-devils | E37: 85699 | F37: 3.76 | G37: 6 | H37: 3081 | I37: Scarlett Press | K37: Podium Audio | L37: Noel Regis | M37: 46282 | N37: Sakshi Saxena | O37: 46286 | P37: 1_City of Gods and Monsters.docx | Q37: 82_House of Devils
A38: Cambric Creek: Sweet & Steamy Monster Romance | B38: C.M. Nascosta | C38: Werewolf / Shifter Romance | D38: https://www.goodreads.com/series/324507-cambric-creek | E38: 80068 | F38: 3.56 | G38: 5 | H38: 1328 | I38: Tantor Media | J38: Self-Represented / N/A | K38: Tantor Media | L38: Noel Regis | M38: 46282 | N38: Sakshi Saxena | O38: 46286 | P38: 1_Morning Glory Milking Farm.docx | Q38: 84_Cambric Creek
A39: Psy-Changeling | B39: Nalini Singh | C39: Werewolf / Shifter Romance | D39: https://www.goodreads.com/series/41454-psy-changeling | E39: 79221 | F39: 4.08 | G39: 25 | H39: 9672 | I39: Penguin Random House | K39: Tantor Media | L39: Noel Regis | M39: 46282 | N39: Sakshi Saxena | O39: 46286 | P39: 1_Slave to Sensation.docx | Q39: 85_Psy-Changeling
A40: Gods Monsters | B40: Amber V. Nicole | C40: High-Stakes Games & Deadly Trials (Done) | D40: https://www.goodreads.com/series/344354-gods-monsters | E40: 68914 | F40: 4.12 | G40: 5 | H40: 2554 | I40: Penguin Random House | K40: Penguin Random House | L40: Noel Regis | M40: 46282 | N40: Sakshi Saxena | O40: 46286 | P40: 1_The Book of Azrael.docx | Q40: 90_Gods & Monsters
A41: Ravenhood Legacy | B41: Kate Stewart | C41: High Fantasy Court Adventure | D41: https://www.goodreads.com/series/372640-ravenhood-legacy | E41: 56519 | F41: 4.51 | G41: 3 | H41: 1440 | I41: Kensington Publishers | K41: Podium Audio | L41: Noel Regis | M41: 46282 | N41: Sakshi Saxena | O41: 46286 | P41: 1_One Last Rainy Day The Legacy of a Prince.docx | Q41: 96_Ravenhood Legacy Trilogy by Kate Stewart
A42: New York Ruthless | B42: Sadie Kincaid | C42: Gothic Dark Romantasy | D42: https://www.goodreads.com/series/338189-new-york-ruthless | E42: 52627 | F42: 3.89 | G42: 5 | H42: 1392 | I42: Red House Press Ltd | K42: Podium Audio | L42: Noel Regis | M42: 46282 | N42: Sakshi Saxena | O42: 46286 | P42: 1_Ryan Rule.docx | Q42: 100_New York Ruthless
A43: Ti N Gu N C F | B43: Ninan Tan | C43: High Fantasy Court Adventure | D43: https://www.goodreads.com/series/324340-ti-n-gu-n-c-f | E43: 50031 | F43: 4.58 | G43: 8 | H43: 3425 | I43: Indie / Self-Published | J43: Metamorphosis Literary Agency | L43: Noel Regis | M43: 46282 | N43: Noel Regis | P43: 1_Heaven Official's Blessing Tian Guan Ci Fu, Vol. 1.docx | Q43: 天官赐福 [Tiān Guān Cì Fú]
A44: Kings of Mafia | B44: Michelle Heard | C44: Gothic Dark Romantasy | D44: https://www.goodreads.com/series/352300-kings-of-mafia | E44: 43705 | F44: 3.82 | G44: 10 | H44: 3464 | I44: MA Heard | K44: Podium Audio | L44: Noel Regis | M44: 46282 | N44: Sakshi Saxena | O44: 46286 | P44: 1_Tempted by the Devil.docx | Q44: 106_Kings of Mafia
A45: He Who Fights with Monsters | B45: Shirtaloon | C45: High Fantasy Court Adventure | D45: https://www.goodreads.com/series/319859-he-who-fights-with-monsters | E45: 43242 | F45: 4.33 | G45: 13 | H45: 8121 | I45: Self Published | K45: Podium Audio | L45: Noel Regis | M45: 46282 | N45: Sakshi Saxena | O45: 46286 | P45: 1_He Who Fights with Monsters.docx | Q45: 107_He Who Fights with Monsters
...

Sheet Batch 2 - 239
A1: Series Name | B1: Author | C1: Sub-Genre | D1: Book Series (GoodReads URL) | E1: GoodReads No. of Ratings | F1: Goodreads Book 1 Ratings | G1: Total Primary Books | H1: Total primary Books Page Count | I1: Imprint / Publisher - Book | J1: Agencies | K1: Imprint / Publisher - Audiobook | L1: Crawling POC | M1: Crawling Date | N1: Links addition POC | O1: Links Date | P1: Book 1 Link | Q1: Books (1 - 5) Links | R1: Check | S1: Batch Number
A2: Grimm Cove | B2: Allyson Voller | C2: War College / Military Academy | D2: https://www.goodreads.com/series/283257-grimm-cove | E2: 5633 | F2: 4.28 | G2: 7 | H2: 3253 | I2: ) Format: Audible Audiobook | J2: New Keywords - Amazon | L2: Anvita Belawal | M2: 46287 | N2: Vanshika V | P2: https://docs.google.com/document/d/1D1lP5ohPnLWRo2ix-7m9UGcX20TDb_iJ/edit?usp=drive_link&ouid=101023058405307348147&rtpof=true&sd=true | Q2: https://drive.google.com/drive/folders/18Fd2l03ZEwdYRezrQG--EeXrMtXG2ZmJ?usp=drive_link | R2: =IF(E2=H2,"Don't Proceed","Proceed")
A3: Solar Dragons Need Love, Too! | B3: Virgil Knightley | C3: Romantasy | D3: https://www.goodreads.com/series/348358-solar-dragons-need-love-too | E3: 5580 | F3: 4.23 | G3: 8 | H3: 2389 | I3: Eldritch Blade | J3: New Keywords - Amazon | L3: Anvita Belawal | M3: 46287 | N3: Vanshika V | P3: https://docs.google.com/document/d/1TFI-vQdDvWlP3Ehjx8yOklOT5Q0_a-gh/edit?usp=drive_link&ouid=101023058405307348147&rtpof=true&sd=true | Q3: https://drive.google.com/drive/folders/1PLZZRRhW2R0aL4NwUl9C9DtvXuPyO2e1?usp=drive_link | R3: =IF(E3=H3,"Don't Proceed","Proceed")
A4: Cora Roberts | B4: Adaline Winters | C4: Paranormal Romance | D4: https://www.goodreads.com/series/365903-cora-roberts | E4: 5579 | G4: 5 | H4: 1368 | I4: Indie / Self-Published | J4: Self-Represented / N/A | K4: Tantor Media | L4: Anvita Belawal | M4: 46287 | N4: Vanshika V | P4: https://docs.google.com/document/d/1rRG2x5zeSbaI1LaHHa-PreqXBG28TEN-/edit?usp=drive_link&ouid=101023058405307348147&rtpof=true&sd=true | Q4: https://drive.google.com/drive/folders/1xB24WnEwcdY6339a5LnsrT2UP__H5T-j?usp=drive_link | R4: =IF(E4=H4,"Don't Proceed","Proceed")
A5: Bewitched by Chocolate Cozy Fantasy Witch Mysteries | B5: H.Y. Hanna | C5: Gothic Dark Romantasy | D5: https://www.goodreads.com/series/198475-bewitched-by-chocolate | E5: 5421 | F5: 4.12 | G5: 9 | H5: 3560 | I5: H.Y. Hanna | J5: New Keywords - Amazon | L5: Anvita Belawal | M5: 46287 | N5: Vanshika V | P5: https://docs.google.com/document/d/1zCCWwUhcG2yadr5oH7pd-a3vHm2SKL8Q/edit?usp=drive_link&ouid=101023058405307348147&rtpof=true&sd=true | Q5: https://drive.google.com/drive/folders/1K093KyAnkb8ydJONVS66fz5I9CKwvpTl?usp=drive_link | R5: =IF(E5=H5,"Don't Proceed","Proceed")
A6: Banished Midlife Dragon Shifters | B6: Alicia Banks | C6: Werewolf / Shifter Romance ( Done ) | D6: https://www.goodreads.com/series/377942-banished-midlife-dragon-shifters | E6: 5410 | F6: 4.58 | G6: 6 | H6: 1289 | I6: Indie / Self-Published | J6: New Keywords - Amazon | L6: Anvita Belawal | M6: 46287 | N6: Vanshika V | P6: https://docs.google.com/document/d/1fIHAM0zrQGal-kxZma4jsYvivoK_lIee/edit?usp=drive_link&ouid=101023058405307348147&rtpof=true&sd=true | Q6: https://drive.google.com/drive/folders/1n1G0ApQH1qwjMNZpddviDGLmdsuNInyP?usp=drive_link | R6: =IF(E6=H6,"Don't Proceed","Proceed")
A7: Souls Trilogy by Harley Laroux | B7: Harley LaRoux | C7: High-Stakes Games & Deadly Trials (Done) | D7: https://www.goodreads.com/series/315325-souls-trilogy | E7: 5403 | F7: 4.02 | G7: 3 | H7: 1652 | I7: Indie / Self-Published | J7: New Keywords - Amazon | L7: Anvita Belawal | M7: 46287 | N7: Vanshika V | P7: https://docs.google.com/document/d/1sTG1wwJfUyuhE0Au_S1t_AuW3TO0af3d/edit?usp=drive_link&ouid=101023058405307348147&rtpof=true&sd=true | Q7: https://drive.google.com/drive/folders/1kx06NHE9WOiCvhEqWgFyEAymr5ZFylAJ?usp=drive_link | R7: =IF(E7=H7,"Don't Proceed","Proceed")
A8: A Throne for Sisters | B8: Morgan Rice | C8: High Fantasy Court Adventure | D8: https://www.goodreads.com/series/223508-a-throne-for-sisters | E8: 5307 | F8: 3.46 | G8: 8 | H8: 1453 | I8: Indie / Self-Published | J8: Self-Represented / N/A | K8: Indie / Self-Published | L8: Anvita Belawal | M8: 46287 | N8: Vanshika V | P8: https://docs.google.com/document/d/1rWM2RUo8weRip-_wik-9nJv_ljn5eddl/edit?usp=drive_link&ouid=101023058405307348147&rtpof=true&sd=true | Q8: https://drive.google.com/drive/folders/1DAePey26qFxpOvVAOQDLsT_PdWeakn4t?usp=drive_link | R8: =IF(E8=H8,"Don't Proceed","Proceed")
A9: Possessive Monsters | B9: Maggie Mayhem | C9: Monster Romance ( Non-Shifter ) | D9: https://www.goodreads.com/series/362691-possessive-monsters | E9: 5288 | F9: 3.94 | G9: 8 | H9: 2009 | I9: Amazon.com Services LLC Explore more items Feral Shifters | J9: New Keywords - Amazon | L9: Anvita Belawal | M9: 46287 | N9: Vanshika V | P9: https://docs.google.com/document/d/1XLGDaG2j-3ER2q2LY9KPTjSuWAkG5TLk/edit?usp=drive_link&ouid=101023058405307348147&rtpof=true&sd=true | Q9: https://drive.google.com/drive/folders/1fS66x_MD9OBCM5Ynf7ufrcyCy-s3HhEr?usp=drive_link | R9: =IF(E9=H9,"Don't Proceed","Proceed")
A10: Immortal Ops | B10: Mandy M. Roth | C10: War College / Military Academy | D10: https://www.goodreads.com/series/47805-immortal-ops | E10: 5273 | F10: 3.91 | G10: 11 | H10: 2745 | I10: The Raven Books | J10: New Keywords - Amazon | L10: Anvita Belawal | M10: 46287 | N10: Vanshika V | P10: https://docs.google.com/document/d/1H3mkEHwshrv43LQ6pS9Kd6fvxrubmVl1/edit?usp=drive_link&ouid=101023058405307348147&rtpof=true&sd=true | Q10: https://drive.google.com/drive/folders/1fbLl54z4PohTCGd5yyV77zWDxwsYJG36?usp=drive_link | R10: =IF(E10=H10,"Don't Proceed","Proceed")
A11: Federal Bureau of Magic | B11: Annabel Chase | C11: Paranormal Romance ( Done ) | D11: https://www.goodreads.com/series/256584-federal-bureau-of-magic | E11: 5220 | F11: 4.15 | G11: 15 | H11: 4839 | I11: ) Format: Audible Audiobook | J11: New Keywords - Amazon | L11: Anvita Belawal | M11: 46287 | N11: Vanshika V | P11: https://docs.google.com/document/d/1p8g8iwoWqq0-7AlvZ9RrTJJXtXxbBuV9/edit?usp=drive_link&ouid=101023058405307348147&rtpof=true&sd=true | Q11: https://drive.google.com/drive/folders/1zArALSBbVzyioEv3pEuFxHq6rKIyxJT3?usp=drive_link | R11: =IF(E11=H11,"Don't Proceed","Proceed")
A12: Mackenzie Green Series | B12: JS Kennedy | C12: High Fantasy Court Adventure | D12: https://www.goodreads.com/series/352234-mackenzie-green | E12: 5208 | F12: 4.22 | G12: 5 | H12: 1932 | I12: Indie / Self-Published | J12: New Keywords - Amazon | L12: Anvita Belawal | M12: 46287 | N12: Vanshika V | P12: https://docs.google.com/document/d/1jwS0VqK3QNVu4FiXNOym5aDBy96ujPbN/edit?usp=drive_link&ouid=101023058405307348147&rtpof=true&sd=true | Q12: https://drive.google.com/drive/folders/1r7tNCriRKAIk-XKVhIMNwAQGCqpwkwyS?usp=drive_link | R12: =IF(E12=H12,"Don't Proceed","Proceed")
A13: Rise of the Warlords | B13: Gena Showalter | C13: Mythology, Legend & Fairy Tale Retelling | D13: https://www.goodreads.com/series/295817-rise-of-the-warlords | E13: 5182 | F13: 4.15 | G13: 4 | H13: 1510 | I13: HQN Books | J13: Self-Represented / N/A | K13: Indie / Self-Published | L13: Anvita Belawal | M13: 46287 | N13: Vanshika V | P13: https://docs.google.com/document/d/1KPYMhRmiG04oi_4DczbDUotwL2i7H9mQ/edit?usp=drive_link&ouid=101023058405307348147&rtpof=true&sd=true | Q13: https://drive.google.com/drive/folders/1k6aXQKZeFe7cyEKYDOM0-kIwM2FYVcBj?usp=drive_link | R13: =IF(E13=H13,"Don't Proceed","Proceed")
A14: The Companion series | B14: Karen Moderow | C14: High Fantasy Court Adventure | D14: https://www.goodreads.com/series/315433-the-companion | E14: 5127 | F14: 3.87 | G14: 6 | H14: 1951 | I14: Indie / Self-Published | J14: New Keywords - Amazon | L14: Anvita Belawal | M14: 46287 | N14: Vanshika V | P14: https://docs.google.com/document/d/1ZmOyEU3TzZce-joodj4kRejjedbC-Rlx/edit?usp=drive_link&ouid=101023058405307348147&rtpof=true&sd=true | Q14: https://drive.google.com/drive/folders/1h3ANH9Jfk7vDPwk_qRERJKwaDSFTe1qf?usp=drive_link | R14: =IF(E14=H14,"Don't Proceed","Proceed")
A15: Demigods Academy series | B15: Elisa S. Amore | C15: War College / Military Academy | D15: https://www.goodreads.com/series/274428-demigods-academy | E15: 5090 | F15: 4.19 | G15: 12 | H15: 2844 | I15: Amore Publishing | J15: New Keywords - Amazon | L15: Anvita Belawal | M15: 46287 | N15: Vanshika V | P15: https://docs.google.com/document/d/1Wy_kLGEzEdE_FKq_fygCtV63IqQDpcWf/edit?usp=drive_link&ouid=101023058405307348147&rtpof=true&sd=true | Q15: https://drive.google.com/drive/folders/1ja6Xlq0k98D0kgBtEDxPGGnZzIuSCrV0?usp=drive_link | R15: =IF(E15=H15,"Don't Proceed","Proceed")
A16: Sons of Sin | B16: Helen Hardt | C16: High Fantasy Court Adventure | D16: https://www.goodreads.com/series/75749-sons-of-sin | E16: 5080 | F16: 3.8 | G16: 4 | H16: 1628 | I16: Indie / Self-Published | J16: New Keywords - Amazon | L16: Anvita Belawal | M16: 46287 | N16: Vanshika V | P16: https://docs.google.com/document/d/1Vxc6n6t2_bhGfP5V_h4ruPcqC95623FC/edit?usp=drive_link&ouid=101023058405307348147&rtpof=true&sd=true | Q16: https://drive.google.com/drive/folders/1SF53QhlN5riFrMClGCkySNdAR_nhNVIq?usp=drive_link | R16: =IF(E16=H16,"Don't Proceed","Proceed")
A17: The Omega Book Club | B17: Veronica Samek | C17: Werewolf / Shifter Romance | D17: https://www.goodreads.com/series/423936-the-omega-book-club | E17: 5060 | F17: 3.77 | G17: 5 | H17: 1203 | I17: Indie / Self-Published | J17: Self-Represented / N/A | K17: Indie / Self-Published | L17: Anvita Belawal | M17: 46287 | N17: Vanshika V | P17: https://docs.google.com/document/d/1SmzR1Nr0kX2yh_FaKTwgiK2m1E_iwUnw/edit?usp=drive_link&ouid=101023058405307348147&rtpof=true&sd=true | Q17: https://drive.google.com/drive/folders/19C9nOjxeHx561xeFfDxSQixdPAbShrH7?usp=drive_link | R17: =IF(E17=H17,"Don't Proceed","Proceed")
A18: The Splintered Bond | B18: Merri Bright | C18: Werewolf / Shifter Romance | D18: https://www.goodreads.com/series/428579-the-splintered-bond | E18: 5020 | G18: 5 | H18: 1695 | I18: Indie / Self-Published | J18: Self-Represented / N/A | K18: Indie / Self-Published | L18: Anvita Belawal | M18: 46287 | N18: Sakshi Saxena | P18: https://docs.google.com/document/d/1up4RHzmHZF_YWDXy1nib3ylrN6vErHsZ/edit?usp=drive_link&ouid=101023058405307348147&rtpof=true&sd=true | Q18: The Splintered Bond | R18: =IF(E18=H18,"Don't Proceed","Proceed")
A19: A Harper Harlow Mystery | B19: Lily Harper Hart | C19: Hidden Magic Romance | D19: https://www.goodreads.com/series/161135-harper-harlow | E19: 4990 | F19: 4.22 | G19: 21 | H19: 4406 | I19: HarperHart Publications | J19: New Keywords - Amazon | L19: Anvita Belawal | M19: 46287 | N19: Sakshi Saxena | P19: https://docs.google.com/document/d/13cJcbkN0w-on9pmpyuQIyeUB6H8TO3WS/edit?usp=drive_link&ouid=101023058405307348147&rtpof=true&sd=true | Q19: A Harper Harlow Mystery | R19: =IF(E19=H19,"Don't Proceed","Proceed")
A20: Starfall Academy | B20: Lyra Mishon | C20: War College / Military Academy | D20: https://www.goodreads.com/series/431968-starfall-academy | E20: 4986 | F20: 4.01 | G20: 4 | H20: 1402 | I20: Indie / Self-Published | J20: Self-Represented / N/A | K20: Indie / Self-Published | L20: Anvita Belawal | M20: 46287 | N20: Sakshi Saxena | P20: https://docs.google.com/document/d/11P4uAvZugRVIuHO1SuymxuuHfIunksnh/edit?usp=drive_link&ouid=101023058405307348147&rtpof=true&sd=true | Q20: Starfall Academy | R20: =IF(E20=H20,"Don't Proceed","Proceed")
A21: The Andari Chronicles | B21: Krista Luna | C21: Subjective | D21: https://www.goodreads.com/series/180512-andari-chronicles | E21: 4943 | F21: 4.09 | G21: 8 | H21: 3695 | I21: Indie / Self-Published | J21: New Keywords - Amazon | L21: Anvita Belawal | M21: 46287 | N21: Sakshi Saxena | P21: https://docs.google.com/document/d/1VZ4PjuKBKifnb_XE4aPR60Uyy9ak_nZ2/edit?usp=drive_link&ouid=101023058405307348147&rtpof=true&sd=true | Q21: The Andari Chronicles | R21: =IF(E21=H21,"Don't Proceed","Proceed")
A22: The Chronicles of Kerrigan | B22: WJ May | C22: High Fantasy Court Adventure | D22: https://www.goodreads.com/series/74270-the-chronicles-of-kerrigan | E22: 4935 | F22: 3.95 | G22: 12 | H22: 2849 | I22: Dark Shadow Publishing | J22: New Keywords - Amazon | L22: Anvita Belawal | M22: 46287 | N22: Sakshi Saxena | P22: https://docs.google.com/document/d/1g1Lm3JKllhCMpwTEfaoOGqEYnLQwSwCY/edit?usp=drive_link&ouid=101023058405307348147&rtpof=true&sd=true | Q22: The Chronicles of Kerrigan | R22: =IF(E22=H22,"Don't Proceed","Proceed")
A23: The Invisible College | B23: Jeff Wheeler | C23: High Fantasy Court Adventure | D23: https://www.goodreads.com/series/411086-the-invisible-college | E23: 4933 | F23: 4.2 | G23: 4 | H23: 1480 | I23: 47North | J23: Self-Represented / N/A | K23: Podium Audio | L23: Anvita Belawal | M23: 46287 | N23: Sakshi Saxena | P23: https://docs.google.com/document/d/1hZEpwLVZjOv2Pd6lL01M2TXoKz6PcoxJ/edit?usp=drive_link&ouid=101023058405307348147&rtpof=true&sd=true | Q23: The Invisible College | R23: =IF(E23=H23,"Don't Proceed","Proceed")
A24: Shadow Series | B24: T. M. Hart | C24: Gothic Dark Romantasy | D24: https://www.goodreads.com/series/210098-shadow | E24: 4886 | F24: 3.89 | G24: 4 | H24: 1279 | I24: Indie / Self-Published | J24: Self-Represented / N/A | K24: Audible Studios | L24: Anvita Belawal | M24: 46287 | N24: Sakshi Saxena | P24: https://docs.google.com/document/d/1WQDbN9jTidoPYH4MXYy6qm8eepLUpehP/edit?usp=drive_link&ouid=101023058405307348147&rtpof=true&sd=true | Q24: Shadow Series | R24: =IF(E24=H24,"Don't Proceed","Proceed")
A25: I Bring the Fire | B25: C. Gockel | C25: Gothic Dark Romantasy | D25: https://www.goodreads.com/series/95355-i-bring-the-fire | E25: 4859 | F25: 3.78 | G25: 8 | H25: 3242 | I25: Amazon Digital Services | J25: New Keywords - Amazon | L25: Anvita Belawal | M25: 46287 | N25: Sakshi Saxena | P25: https://docs.google.com/document/d/1qKNS7hdv75OzjXXihyAs-QogxPksJhOb/edit?usp=drive_link&rtpof=true&sd=true | Q25: I Bring the Fire | R25: =IF(E25=H25,"Don't Proceed","Proceed")
A26: The Killian Blade Series | B26: Stella Brie | C26: Urban Fantasy Romance | D26: https://www.goodreads.com/series/309871-killian-blade | E26: 4831 | F26: 4.2 | G26: 6 | H26: 1913 | I26: Stella Brie | J26: New Keywords - Amazon | L26: Anvita Belawal | M26: 46287 | N26: Sakshi Saxena | P26: https://docs.google.com/document/d/1OsGpVyoFnU6lzLPC-g3uDMqOwKA1bDUD/edit?usp=drive_link&ouid=101023058405307348147&rtpof=true&sd=true | Q26: The Killian Blade Series | R26: =IF(E26=H26,"Don't Proceed","Proceed")
A27: PSI-Ops/Immortal Ops | B27: Mandy M. Roth | C27: War College / Military Academy | D27: https://www.goodreads.com/series/137832-immortal-ops-psi-ops | E27: 4753 | F27: 4.12 | G27: 8 | H27: 3263 | I27: Raven Happy Hour, LLC | J27: New Keywords - Amazon | L27: Anvita Belawal | M27: 46287 | N27: Sakshi Saxena | P27: https://docs.google.com/document/d/1svKaAQD3a52-B0EHuRygSWBkw1vCE17H/edit?usp=drive_link&ouid=101023058405307348147&rtpof=true&sd=true | Q27: PSI-Ops_Immortal Ops | R27: =IF(E27=H27,"Don't Proceed","Proceed")
A28: Shadow Quest | B28: Kiersten Fay | C28: Gothic Dark Romantasy | D28: https://www.goodreads.com/series/60693-shadow-quest | E28: 4722 | F28: 3.92 | G28: 4 | H28: 1718 | I28: ), Henry Jones (Narrator) Format: Audible Audiobook | J28: New Keywords - Amazon | L28: Anvita Belawal | M28: 46287 | N28: Sakshi Saxena | P28: https://docs.google.com/document/d/1SVoEvGe4GwJfGZsiiQZWsQ9ccJQbWrgd/edit?usp=drive_link&ouid=101023058405307348147&rtpof=true&sd=true | Q28: Shadow Quest | R28: =IF(E28=H28,"Don't Proceed","Proceed")
